<mujoco model="bdx">
  <compiler angle="radian" meshdir="meshes" texturedir="textures"/>

  <option timestep="0.001"/>

  <default>
    <default class="bdx">
      <!-- <geom material="bdx" group="2"/> -->
    </default>

    <default class="go1-leg">
      <joint damping="1.3" frictionloss="0.1"/>
      <position kp="40" forcerange="-23.7 23.7" ctrlrange="-0.785398 0.785398" forcelimited="true" ctrllimited="true"/>
    </default>

    <default class="go1-ankle">
      <joint damping="1.6" frictionloss="0.1"/>
      <position kp="30" forcerange="-23.7 23.7" ctrlrange="-0.785398 0.785398" forcelimited="true" ctrllimited="true"/>
    </default>

    <default class="go1-neck">
      <joint damping="1.3" frictionloss="0.1"/>
      <position kp="40" forcerange="-23.7 23.7" ctrlrange="-0.785398 0.785398" forcelimited="true" ctrllimited="true"/>
    </default>

    <default class="dynamixel">
      <joint damping="1.0" frictionloss="0.05"/>
      <position kp="15" forcerange="-7.3 7.3" ctrlrange="-0.785398 0.785398" forcelimited="true" ctrllimited="true"/>
    </default>

    <default class="antenna">
      <joint damping="0.2" frictionloss="0.02"/>
      <position kp="3" forcerange="-3.0 3.0" ctrlrange="-0.785398 0.785398" forcelimited="true" ctrllimited="true"/>
    </default>
  </default>

  <asset>
    <!-- <texture name="bdx" file="bdx-texture.png" type="2d"/> -->
    <!-- <material name="bdx" texture="bdx"/> -->
    <mesh name="pelvis" file="pelvis.stl" scale="0.001 0.001 0.001"/>
    <mesh name="left_foot" file="left_foot.stl" scale="0.001 0.001 0.001"/>
    <mesh name="left_shin" file="left_shin.stl" scale="0.001 0.001 0.001"/>
    <mesh name="left_thigh" file="left_thigh.stl" scale="0.001 0.001 0.001"/>
    <mesh name="left_hip" file="left_hip.stl" scale="0.001 0.001 0.001"/>
    <mesh name="left_hip_rotation" file="left_hip_rotation.stl" scale="0.001 0.001 0.001"/>
    <mesh name="right_foot" file="right_foot.stl" scale="0.001 0.001 0.001"/>
    <mesh name="right_shin" file="right_shin.stl" scale="0.001 0.001 0.001"/>
    <mesh name="right_thigh" file="right_thigh.stl" scale="0.001 0.001 0.001"/>
    <mesh name="right_hip" file="right_hip.stl" scale="0.001 0.001 0.001"/>
    <mesh name="right_hip_rotation" file="right_hip_rotation.stl" scale="0.001 0.001 0.001"/>
    <mesh name="ear_right" file="ear_right.stl" scale="0.001 0.001 0.001"/>
    <mesh name="ear_left" file="ear_left.stl" scale="0.001 0.001 0.001"/>
    <mesh name="head_body_roll" file="head_body_roll.stl" scale="0.001 0.001 0.001"/>
    <mesh name="head_body_yaw" file="head_body_yaw.stl" scale="0.001 0.001 0.001"/>
    <mesh name="head_body_pitch" file="head_body_pitch.stl" scale="0.001 0.001 0.001"/>
    <mesh name="neck" file="neck.stl" scale="0.001 0.001 0.001"/>
  </asset>
  <worldbody>
    <light name="spotlight" mode="targetbodycom" target="bdx" pos="0 -1 2"/>
    <body name="bdx">
      <camera name="track" pos="0 -3 1" zaxis="0 -1 0.5" mode="track"/>
      <freejoint/>
      <body name="pelvis" pos="0 0 0" childclass="bdx">
        <geom type="mesh" rgba="0.7 0.7 0.7 1" mesh="pelvis"/>
        <inertial pos="0 0 0" quat="0 0 0 1" mass="5.713" diaginertia="0.201691 0.431684 0.371809"/>
        <site name="imu" pos="0 0 0"/>
        <body name="left_hip_rotation" pos="-0.033111 0.046658 0.363959">
          <inertial pos="-0.00508397 0.00309242 -0.0631043" quat="0.999573 0.0213461 0.0199274 0.00141326" mass="0.633" diaginertia="0.00533636 0.004183 0.00196963"/>
          <joint class="go1-leg" name="left_hip_yaw" pos="0 0 0" axis="0 0 -1"/>
          <geom pos="0.033111 -0.046658 -0.363959" type="mesh" rgba="0.7 0.7 0.7 1" mesh="left_hip_rotation"/>
          <body name="left_hip" pos="-0.0073 0.00275 -0.076">
            <inertial pos="0.0189112 0.0234713 0.000362123" quat="0.704899 0.708795 -0.00571972 -0.0263546" mass="0.633" diaginertia="0.00149816 0.00136791 0.000505934"/>
            <joint class="go1-leg" name="left_hip_roll" pos="0 0 0" axis="1 0 0"/>
            <geom pos="0.040411 -0.049408 -0.287959" quat="1 0 0 0" type="mesh" rgba="0.7 0.7 0.7 1" mesh="left_hip"/>
            <body name="left_thigh" pos="0.017466 0.069601 0.000785">
              <inertial pos="-0.0341087 0.0267727 -0.0344467" quat="0.633403 0.297734 0.294346 0.650781" mass="0.633" diaginertia="0.0473468 0.0413446 0.0120747"/>
              <joint class="go1-leg" name="left_hip_pitch" pos="0 0 0" axis="0 1 0"/>
              <geom pos="0.022945 -0.119009 -0.288744" quat="1 0 0 0" type="mesh" rgba="0.7 0.7 0.7 1" mesh="left_thigh"/>
              <body name="left_shin" pos="-0.079306 0 -0.077708">
                <inertial pos="0.0222946 -0.0149367 -0.0900588" quat="0.708097 -0.166338 -0.130184 0.673783" mass="0.633" diaginertia="0.0117688 0.0102167 0.00215741"/>
                <joint class="go1-leg" name="left_knee" pos="0 0 0" axis="0 -1 0"/>
                <geom pos="0.102251 -0.119009 -0.211036" quat="1 0 0 0" type="mesh" rgba="0.7 0.7 0.7 1" mesh="left_shin"/>
                <body name="left_foot_link" pos="0.045 -0.0152 -0.13">
                  <inertial pos="0.0317645 0.00793337 -0.0421515" quat="0.540863 0.468785 0.58167 0.386481" mass="0.678" diaginertia="0.0103795 0.00833717 0.00325637"/>
                  <joint class="go1-ankle" name="left_ankle" pos="0 0 0" axis="0 1 0"/>
                  <geom pos="0.057251 -0.103809 -0.081036" quat="1 0 0 0" type="mesh" rgba="0.7 0.7 0.7 1" mesh="left_foot"/>
                </body>
              </body>
            </body>
          </body>
        </body>
       <body name="right_hip_rotation" pos="-0.033111 -0.046658 0.363959">
          <inertial pos="-0.00508397 -0.00309242 -0.0631043" quat="0.999573 -0.0213461 0.0199274 -0.00141326" mass="0.633" diaginertia="0.00533636 0.004183 0.00196963"/>
          <joint class="go1-leg" name="right_hip_yaw" pos="0 0 0" axis="0 0 -1"/>
          <geom pos="0.033111 0.046658 -0.363959" type="mesh" rgba="0.7 0.7 0.7 1" mesh="right_hip_rotation"/>
          <body name="right_hip" pos="-0.0073 -0.00275 -0.076">
            <inertial pos="0.0189112 -0.0234713 0.000362123" quat="0.708795 0.704899 0.0263546 0.00571972" mass="0.633" diaginertia="0.00149816 0.00136791 0.000505934"/>
            <joint class="go1-leg" name="right_hip_roll" pos="0 0 0" axis="1 0 0"/>
            <geom pos="0.040411 0.049408 -0.287959" quat="1 0 0 0" type="mesh" rgba="0.7 0.7 0.7 1" mesh="right_hip"/>
            <body name="right_thigh" pos="0.017466 -0.069601 0.000785">
              <inertial pos="-0.0341087 -0.0267727 -0.0344467" quat="0.650781 0.294346 0.297734 0.633403" mass="0.633" diaginertia="0.0473468 0.0413446 0.0120747"/>
              <joint class="go1-leg" name="right_hip_pitch" pos="0 0 0" axis="0 -1 0"/>
              <geom pos="0.022945 0.119009 -0.288744" quat="1 0 0 0" type="mesh" rgba="0.7 0.7 0.7 1" mesh="right_thigh"/>
              <body name="right_shin" pos="-0.079306 0 -0.077708">
                <inertial pos="0.0222946 0.0149367 -0.0900588" quat="0.673783 -0.130184 -0.166338 0.708097" mass="0.633" diaginertia="0.0117688 0.0102167 0.00215741"/>
                <joint class="go1-leg" name="right_knee" pos="0 0 0" axis="0 1 0"/>
                <geom pos="0.102251 0.119009 -0.211036" quat="1 0 0 0" type="mesh" rgba="0.7 0.7 0.7 1" mesh="right_shin"/>
                <body name="right_foot_link" pos="0.045 0.0152 -0.13">
                  <inertial pos="0.0317645 -0.00793337 -0.0421515" quat="0.386481 0.58167 0.468785 0.540863" mass="0.678" diaginertia="0.0103795 0.00833717 0.00325637"/>
                  <joint class="go1-ankle" name="right_ankle" pos="0 0 0" axis="0 -1 0"/>
                  <geom pos="0.057251 0.103809 -0.081036" quat="1 0 0 0" type="mesh" rgba="0.7 0.7 0.7 1" mesh="right_foot"/>
                </body>
              </body>
            </body>
           </body>
        </body>
        <body name="neck" pos="0.056339 0.0119 0.395171">
          <inertial pos="-0.0240043 -0.0164112 0.050435" quat="0.415022 -0.234316 -0.0652626 0.876694" mass="0.633" diaginertia="0.00651818 0.00640093 0.00104188"/>
          <joint class="go1-neck" name="neck_pitch" pos="0 0 0" axis="0 -1 0"/>
          <geom pos="-0.056339 -0.0119 -0.395171" quat="1 0 0 0" type="mesh" rgba="0.7 0.7 0.7 1" mesh="neck"/>
          <body name="head_body_pitch" pos="-0.065022 -0.01175 0.11088">
            <inertial pos="-0.0129682 -0.00171465 0.0277559" quat="0.975914 -0.0920927 -0.197246 0.0143444" mass="0.2" diaginertia="0.000404789 0.00034123 0.000159981"/>
            <joint class="dynamixel" name="head_pitch" pos="0 0 0" axis="0 -1 0"/>
            <geom pos="0.008683 -0.00015 -0.506051" type="mesh" rgba="0.7 0.7 0.7 1" mesh="head_body_pitch"/>
            <body name="head_body_yaw" pos="0.000299 0.0007 0.02897">
              <inertial pos="0.00785461 -1.46108e-06 0.0225451" quat="0.541584 0.454629 0.454629 0.541584" mass="0.2" diaginertia="0.000559 0.000550027 0.000215973"/>
              <joint class="dynamixel" name="head_yaw" pos="0 0 0" axis="0 0 1"/>
              <geom pos="0.008384 -0.00085 -0.535021" quat="1 0 0 0" type="mesh" rgba="0.7 0.7 0.7 1" mesh="head_body_yaw"/>
              <body name="head_body_roll" pos="0.039892 0 0.02715">
                <inertial pos="-0.0339687 0.00148766 0.00242765" quat="-0.0651364 0.688995 0.064254 0.718968" mass="0.4" diaginertia="0.0807248 0.047202 0.0412992"/>
                <joint class="dynamixel" name="head_roll" pos="0 0 0" axis="1 0 0"/>
                <geom pos="-0.031508 -0.00085 -0.562171" quat="1 0 0 0" type="mesh" rgba="0.7 0.7 0.7 1" mesh="head_body_roll"/>
                <body name="ear_left" pos="-0.16665 0.0683 0.001231">
                  <inertial pos="0.000161565 0.0247291 0.016145" quat="0.998004 -0.0231719 0.0382937 0.0445513" mass="0.0964016" diaginertia="0.000208107 0.000200388 1.95059e-05"/>
                  <joint class="antenna" name="left_antenna" pos="0 0 0" axis="0 -1 0"/>
                  <geom pos="0.135142 -0.06915 -0.563402" quat="1 0 0 0" type="mesh" rgba="0.7 0.7 0.7 1" mesh="ear_left"/>
                </body>
                <body name="ear_right" pos="-0.16665 -0.0697 0.001231">
                  <inertial pos="0.000161565 -0.0247291 0.016145" quat="0.998004 0.0231719 0.0382937 -0.0445513" mass="0.0964016" diaginertia="0.000208107 0.000200388 1.95059e-05"/>
                  <joint class="antenna" name="right_antenna" pos="0 0 0" axis="0 -1 0"/>
                  <geom pos="0.135142 0.06885 -0.563402" type="mesh" rgba="0.7 0.7 0.7 1" mesh="ear_right"/>
                </body>
              </body>
            </body>
          </body>
        </body>
      </body>
    </body>
  </worldbody>
  <contact>
    <exclude body1="pelvis" body2="right_hip"/>
    <exclude body1="pelvis" body2="left_hip"/>
    <exclude body1="neck" body2="head_body_pitch"/>
    <exclude body1="neck" body2="head_body_yaw"/>
    <exclude body1="neck" body2="head_body_roll"/>
    <exclude body1="head_body_pitch" body2="head_body_roll"/>
    <exclude body1="head_body_yaw" body2="head_body_roll"/>
  </contact>
  <actuator>
    <position class="go1-leg" name="right_hip_yaw" joint="right_hip_yaw"/>
    <position class="go1-leg" name="right_hip_roll" joint="right_hip_roll"/>
    <position class="go1-leg" name="right_hip_pitch" joint="right_hip_pitch"/>
    <position class="go1-leg" name="right_knee" joint="right_knee"/>
    <position class="go1-ankle" name="right_ankle" joint="right_ankle"/>
    <position class="go1-leg" name="left_hip_yaw" joint="left_hip_yaw"/>
    <position class="go1-leg" name="left_hip_roll" joint="left_hip_roll"/>
    <position class="go1-leg" name="left_hip_pitch" joint="left_hip_pitch"/>
    <position class="go1-leg" name="left_knee" joint="left_knee"/>
    <position class="go1-ankle" name="left_ankle" joint="left_ankle"/>
    <position class="go1-neck" name="neck_pitch" joint="neck_pitch"/>
    <position class="dynamixel" name="head_pitch" joint="head_pitch"/>
    <position class="dynamixel" name="head_yaw" joint="head_yaw"/>
    <position class="dynamixel" name="head_roll" joint="head_roll"/>
    <position class="antenna" name="left_antenna" joint="left_antenna"/>
    <position class="antenna" name="right_antenna" joint="right_antenna"/>
  </actuator>
  <sensor>
    <gyro          name='angular-velocity'    site='imu' noise='0.005' cutoff='34.9'/>
    <velocimeter   name='linear-velocity'     site='imu' noise='0.001' cutoff='30'/>
    <accelerometer name='linear-acceleration' site='imu' noise='0.005' cutoff='157'/>
  </sensor>
</mujoco>

